<?xml version='1.0' encoding='ASCII'?>
<robot name="simple_planar_robot">
  <link name="base_link"/>
  <link name="link1">
    <visual name="link1_visual">
      <geometry>
        <box size="0.3 0.04 0.04"/>
      </geometry>
      <origin xyz="0.15 0.0 0.0" rpy="0.0 -0.0 0.0"/>
      <material name="gray">
        <color rgba="0.7 0.7 0.7 1.0"/>
      </material>
    </visual>
  </link>
  <link name="ee_link">
    <visual name="ee_visual">
      <geometry>
        <box size="0.05 0.05 0.05"/>
      </geometry>
      <origin xyz="0.0 0.0 0.0" rpy="0.0 -0.0 0.0"/>
      <material name="gray">
        <color rgba="0.7 0.7 0.7 1.0"/>
      </material>
    </visual>
  </link>
  <joint name="joint1" type="revolute">
    <parent link="base_link"/>
    <child link="link1"/>
    <origin xyz="0.0 0.0 0.0" rpy="0.0 -0.0 0.0"/>
    <axis xyz="0.0 0.0 1.0"/>
    <limit effort="1.0" velocity="1.0" lower="-3.141592653589793" upper="3.141592653589793"/>
  </joint>
  <joint name="joint_ee" type="revolute">
    <parent link="link1"/>
    <child link="ee_link"/>
    <origin xyz="0.3 0.0 0.0" rpy="0.0 -0.0 0.0"/>
    <axis xyz="0.0 0.0 1.0"/>
    <limit effort="1.0" velocity="1.0" lower="-3.141592653589793" upper="3.141592653589793"/>
  </joint>
  <material name="gray">
    <color rgba="0.7 0.7 0.7 1.0"/>
  </material>
</robot>
